<?xml version="1.0" encoding="utf-8"?>
<robot name="dvrk_psm" xmlns:xacro="http://www.ros.org/wiki/xacro">

  <xacro:macro name="psm_tool_caudier_blade" params="prefix">
    
    <!-- joint 5: Outer wrist pitch joint -->
    <joint name="outer_wrist_pitch" type="revolute">
      <parent link="${prefix}tool_wrist_shaft_link"/>
      <child link="${prefix}tool_wrist_caudier_link"/>
      <axis xyz="0 0 1"/>
      <origin rpy="-1.5708 -1.5708 0" xyz="0 0 0"/>
      <limit lower="-1.5707" upper="1.5707" velocity=".4" effort="1000"/>
    </joint>
    
    <!-- link 5: tool_wrist_caudier_link -->
    <link name="${prefix}tool_wrist_caudier_link">
      <visual>
        <origin rpy="0.00 -1.5708 0.0" xyz="-0.0024 0.00 0.000"/>
        <geometry>
          <mesh filename="package://dvrk_model/meshes/psm/tool_wrist_caudier_link_1.stl"/>
        </geometry>
        <material name="gray"><color rgba="0.5 0.5 0.9 1.0"/></material>
      </visual>
      <collision>
        <origin rpy="0.00 -1.5708 0.0" xyz="-0.0024 0.00 0.000"/>
        <geometry>
          <mesh filename="package://dvrk_model/meshes/psm/tool_wrist_caudier_link_1.stl"/>
        </geometry>
      </collision>
    </link>

    <!-- joint 6: Tool wrist yaw joint -->
    <joint name="outer_wrist_yaw" type="revolute">
      <parent link="${prefix}tool_wrist_caudier_link"/>
      <child link="${prefix}tool_wrist_caudier_shaft_link"/>
      <axis xyz="0 0 -1"/>
      <origin rpy="0.00 -1.5708 -1.5708" xyz="0.0091 0 0"/>
      <limit lower="-1.5707" upper="1.5707" velocity=".4" effort="1000"/>
    </joint>

    <!-- link 6: tool_wrist_caudier_link_shaft -->
    <link name="${prefix}tool_wrist_caudier_shaft_link">
      <visual>
        <origin rpy="0.00 1.5708 0.0" xyz="0.0 -0.0002 0.000"/>
        <geometry>
          <mesh filename="package://dvrk_model/meshes/psm/tool_wrist_caudier_link_1_shaft.stl"/>
        </geometry>
        <material name="gray"><color rgba="0.5 0.5 0.9 1.0"/></material>
      </visual>
      <collision>
        <origin rpy="0.00 1.5708 0.0" xyz="0.0 0.00 0.000"/>
        <geometry>
          <mesh filename="package://dvrk_model/meshes/psm/tool_wrist_caudier_link_1_shaft.stl"/>
        </geometry>
      </collision>
    </link>
    
    <!-- joint 7-0: Outer open angle 1  -->
    <joint name="jaw" type="fixed">
      <parent link="${prefix}tool_wrist_caudier_shaft_link"/>
      <child link="${prefix}tool_wrist_caudier_ee_link_0"/>      
      <!-- <axis xyz="0 1 0"/> -->
      <origin rpy="0 0 0" xyz="0 0 0"/>
      <!-- <limit lower="0" upper="1.5707" velocity=".4" effort="1000"/> -->
    </joint>

    <!-- link 7-0: Outer open angle virtual -->
    <link name="${prefix}tool_wrist_caudier_ee_link_0">
      <visual>
        <origin rpy="0.0 0.0 0.0" xyz="0 0.0225 0"/>
        <geometry>
          <box size="0.005 0.045 0.001" />
        </geometry>
      </visual>
      <collision>
        <origin rpy="0.0 0.0 0.0" xyz="0 0.0225 0"/>
        <geometry>
          <box size="0.005  0.045 0.001" />
        </geometry>
      </collision>
    </link>

    <!-- tool tip   -->
    <joint name="tool_wrist_caudier_ee" type="fixed">
      <parent link="${prefix}tool_wrist_caudier_ee_link_0"/>
      <child link="${prefix}tool_tip_link"/>      
      <origin rpy="-1.5708 0.0 0.0" xyz="0 0.045 0"/>      
    </joint>

    <!-- link 6-3:  -->
    <link name="${prefix}tool_tip_link" />    

  </xacro:macro>

</robot>


